<?xml version="1.0" encoding="utf-8"?>
<!-- This URDF was automatically created by SolidWorks to URDF Exporter! Originally created by Stephen Brawner (brawner@gmail.com) 
     Commit Version: 1.6.0-4-g7f85cfe  Build Version: 1.6.7995.38578
     For more information, please see http://wiki.ros.org/sw_urdf_exporter -->
<robot
  name="Student_Arm.SLDASM">
  <link
    name="base_link">
    <inertial>
      <origin
        xyz="3.75969511867261E-08 0.00262773702860451 -0.0794517403190993"
        rpy="0 0 0" />
      <mass
        value="0.53383345184999" />
      <inertia
        ixx="0.00120475867367635"
        ixy="-2.59729358055515E-09"
        ixz="1.27494390417928E-09"
        iyy="0.00118360373666522"
        iyz="-4.04496125401077E-08"
        izz="0.00226030030514847" />
    </inertial>
    <visual>
      <origin
        xyz="0 0 0"
        rpy="0 0 0" />
      <geometry>
        <mesh
          filename="package://Student_Arm.SLDASM/meshes/base_link.STL" />
      </geometry>
      <material
        name="">
        <color
          rgba="0.898039215686275 0.898039215686275 0.898039215686275 1" />
      </material>
    </visual>
    <collision>
      <origin
        xyz="0 0 0"
        rpy="0 0 0" />
      <geometry>
        <mesh
          filename="package://Student_Arm.SLDASM/meshes/base_link.STL" />
      </geometry>
    </collision>
  </link>
  <link
    name="J1">
    <inertial>
      <origin
        xyz="8.04561342671343E-17 -0.043916645765684 -0.000151589790021581"
        rpy="0 0 0" />
      <mass
        value="0.503990921516619" />
      <inertia
        ixx="0.000419374261334047"
        ixy="-1.02367902142622E-18"
        ixz="-6.38048695894563E-13"
        iyy="0.000727556052551127"
        iyz="1.14884368640366E-07"
        izz="0.000433260463010681" />
    </inertial>
    <visual>
      <origin
        xyz="0 0 0"
        rpy="0 0 0" />
      <geometry>
        <mesh
          filename="package://Student_Arm.SLDASM/meshes/J1.STL" />
      </geometry>
      <material
        name="">
        <color
          rgba="0.898039215686275 0.917647058823529 0.929411764705882 1" />
      </material>
    </visual>
    <collision>
      <origin
        xyz="0 0 0"
        rpy="0 0 0" />
      <geometry>
        <mesh
          filename="package://Student_Arm.SLDASM/meshes/J1.STL" />
      </geometry>
    </collision>
  </link>
  <joint
    name="J1"
    type="revolute">
    <origin
      xyz="0 0 0"
      rpy="1.5708 0 0" />
    <parent
      link="base_link" />
    <child
      link="J1" />
    <axis
      xyz="0 1 0" />
    <limit
      lower="0"
      upper="0"
      effort="0"
      velocity="0" />
  </joint>
  <link
    name="J2">
    <inertial>
      <origin
        xyz="-0.010657030118576 0.0996091502677743 -0.0223342327191616"
        rpy="0 0 0" />
      <mass
        value="0.392763832529056" />
      <inertia
        ixx="0.000400852871558412"
        ixy="3.07266682045366E-06"
        ixz="4.20751594229321E-08"
        iyy="0.000315828021020535"
        iyz="3.09831448550275E-09"
        izz="0.000172542750828533" />
    </inertial>
    <visual>
      <origin
        xyz="0 0 0"
        rpy="0 0 0" />
      <geometry>
        <mesh
          filename="package://Student_Arm.SLDASM/meshes/J2.STL" />
      </geometry>
      <material
        name="">
        <color
          rgba="1 0.949019607843137 0.874509803921569 1" />
      </material>
    </visual>
    <collision>
      <origin
        xyz="0 0 0"
        rpy="0 0 0" />
      <geometry>
        <mesh
          filename="package://Student_Arm.SLDASM/meshes/J2.STL" />
      </geometry>
    </collision>
  </link>
  <joint
    name="J2"
    type="revolute">
    <origin
      xyz="0.0221 0 0"
      rpy="1.5708 1.0391 1.5708" />
    <parent
      link="J1" />
    <child
      link="J2" />
    <axis
      xyz="0 0 -1" />
    <limit
      lower="-1.4"
      upper="2.5"
      effort="0"
      velocity="0" />
  </joint>
  <link
    name="J3">
    <inertial>
      <origin
        xyz="-5.45271021479277E-06 -0.0961480825762141 0.0185216217058464"
        rpy="0 0 0" />
      <mass
        value="0.208448276188946" />
      <inertia
        ixx="0.000105804377205433"
        ixy="4.28051143309548E-08"
        ixz="8.55997903886123E-10"
        iyy="7.51759600817455E-05"
        iyz="-1.27448182426847E-06"
        izz="7.07511269591069E-05" />
    </inertial>
    <visual>
      <origin
        xyz="0 0 0"
        rpy="0 0 0" />
      <geometry>
        <mesh
          filename="package://Student_Arm.SLDASM/meshes/J3.STL" />
      </geometry>
      <material
        name="">
        <color
          rgba="1 0.949019607843137 0.874509803921569 1" />
      </material>
    </visual>
    <collision>
      <origin
        xyz="0 0 0"
        rpy="0 0 0" />
      <geometry>
        <mesh
          filename="package://Student_Arm.SLDASM/meshes/J3.STL" />
      </geometry>
    </collision>
  </link>
  <joint
    name="J3"
    type="revolute">
    <origin
      xyz="-0.06275 0.242 0"
      rpy="-3.1416 0 1.8245" />
    <parent
      link="J2" />
    <child
      link="J3" />
    <axis
      xyz="0 0 1" />
    <limit
      lower="-1.4"
      upper="1.8"
      effort="0"
      velocity="0" />
  </joint>
  <link
    name="J4">
    <inertial>
      <origin
        xyz="0.000220187546183669 0.00131330393669651 -0.00131330397228385"
        rpy="0 0 0" />
      <mass
        value="0.0607110395840995" />
      <inertia
        ixx="1.24543917386619E-05"
        ixy="-2.80072544359729E-08"
        ixz="2.80072615395426E-08"
        iyy="1.06706749274671E-05"
        iyz="1.97798843517747E-06"
        izz="1.0670674947774E-05" />
    </inertial>
    <visual>
      <origin
        xyz="0 0 0"
        rpy="0 0 0" />
      <geometry>
        <mesh
          filename="package://Student_Arm.SLDASM/meshes/J4.STL" />
      </geometry>
      <material
        name="">
        <color
          rgba="0.776470588235294 0.756862745098039 0.737254901960784 1" />
      </material>
    </visual>
    <collision>
      <origin
        xyz="0 0 0"
        rpy="0 0 0" />
      <geometry>
        <mesh
          filename="package://Student_Arm.SLDASM/meshes/J4.STL" />
      </geometry>
    </collision>
  </link>
  <joint
    name="J4"
    type="revolute">
    <origin
      xyz="0 -0.23213 0.0221"
      rpy="0.7854 1.5708 0" />
    <parent
      link="J3" />
    <child
      link="J4" />
    <axis
      xyz="0 0.70711 -0.70711" />
    <limit
      lower="0"
      upper="0"
      effort="0"
      velocity="0" />
  </joint>
  <link
    name="J5">
    <inertial>
      <origin
        xyz="-0.0193350804383505 0.0351625780910091 7.23341200062768E-05"
        rpy="0 0 0" />
      <mass
        value="0.0534742460950643" />
      <inertia
        ixx="1.00219216800758E-05"
        ixy="-1.68795010015766E-06"
        ixz="1.06688095975439E-14"
        iyy="9.08572755149508E-06"
        iyz="3.80772967325136E-15"
        izz="1.35572846813949E-05" />
    </inertial>
    <visual>
      <origin
        xyz="0 0 0"
        rpy="0 0 0" />
      <geometry>
        <mesh
          filename="package://Student_Arm.SLDASM/meshes/J5.STL" />
      </geometry>
      <material
        name="">
        <color
          rgba="1 0.949019607843137 0.874509803921569 1" />
      </material>
    </visual>
    <collision>
      <origin
        xyz="0 0 0"
        rpy="0 0 0" />
      <geometry>
        <mesh
          filename="package://Student_Arm.SLDASM/meshes/J5.STL" />
      </geometry>
    </collision>
  </link>
  <joint
    name="J5"
    type="revolute">
    <origin
      xyz="0 -0.012639 0.012639"
      rpy="1.5708 0.80221 1.5708" />
    <parent
      link="J4" />
    <child
      link="J5" />
    <axis
      xyz="0 0 1" />
    <limit
      lower="-0.75"
      upper="2.9"
      effort="0"
      velocity="0" />
  </joint>
  <link
    name="J6">
    <inertial>
      <origin
        xyz="-0.00652240568024975 -0.00282934293785489 0.0461121113046438"
        rpy="0 0 0" />
      <mass
        value="0.101334847700238" />
      <inertia
        ixx="1.25179111498773E-05"
        ixy="-3.15702660925521E-06"
        ixz="2.91310652029022E-07"
        iyy="1.83466104184037E-05"
        iyz="1.27578308760004E-07"
        izz="2.05740039349966E-05" />
    </inertial>
    <visual>
      <origin
        xyz="0 0 0"
        rpy="0 0 0" />
      <geometry>
        <mesh
          filename="package://Student_Arm.SLDASM/meshes/J6.STL" />
      </geometry>
      <material
        name="">
        <color
          rgba="1 0.949019607843137 0.874509803921569 1" />
      </material>
    </visual>
    <collision>
      <origin
        xyz="0 0 0"
        rpy="0 0 0" />
      <geometry>
        <mesh
          filename="package://Student_Arm.SLDASM/meshes/J6.STL" />
      </geometry>
    </collision>
  </link>
  <joint
    name="J6"
    type="revolute">
    <origin
      xyz="-0.041089 0.03973 0"
      rpy="1.5708 0.40912 -2.3394" />
    <parent
      link="J5" />
    <child
      link="J6" />
    <axis
      xyz="0 0 1" />
    <limit
      lower="0"
      upper="0"
      effort="0"
      velocity="0" />
  </joint>
  <link
    name="Gripper_Left">
    <inertial>
      <origin
        xyz="-0.0512896051514708 0.00560157688987424 0.501039420387131"
        rpy="0 0 0" />
      <mass
        value="0.0232588565708634" />
      <inertia
        ixx="1.186156607992E-05"
        ixy="-9.35435854349611E-07"
        ixz="3.8463541175853E-06"
        iyy="2.48718738015488E-05"
        iyz="1.86470326420233E-06"
        izz="1.52926077762987E-05" />
    </inertial>
    <visual>
      <origin
        xyz="0 0 0"
        rpy="0 0 0" />
      <geometry>
        <mesh
          filename="package://Student_Arm.SLDASM/meshes/Gripper_Left.STL" />
      </geometry>
      <material
        name="">
        <color
          rgba="0.792156862745098 0.819607843137255 0.933333333333333 1" />
      </material>
    </visual>
    <collision>
      <origin
        xyz="0 0 0"
        rpy="0 0 0" />
      <geometry>
        <mesh
          filename="package://Student_Arm.SLDASM/meshes/Gripper_Left.STL" />
      </geometry>
    </collision>
  </link>
  <joint
    name="GL"
    type="prismatic">
    <origin
      xyz="-0.0010648 0.0024559 -0.41061"
      rpy="0 0 1.9799" />
    <parent
      link="J6" />
    <child
      link="Gripper_Left" />
    <axis
      xyz="1 0 0" />
    <limit
      lower="0"
      upper="0.057"
      effort="0"
      velocity="0" />
  </joint>
  <link
    name="Gripper_Right">
    <inertial>
      <origin
        xyz="0.00339842311012583 -0.0157304521384906 0.0269603948485267"
        rpy="0 0 0" />
      <mass
        value="0.0232588565708632" />
      <inertia
        ixx="2.48718738015488E-05"
        ixy="1.86470326420232E-06"
        ixz="9.35435854349624E-07"
        iyy="1.52926077762988E-05"
        iyz="-3.84635411758521E-06"
        izz="1.18615660799199E-05" />
    </inertial>
    <visual>
      <origin
        xyz="0 0 0"
        rpy="0 0 0" />
      <geometry>
        <mesh
          filename="package://Student_Arm.SLDASM/meshes/Gripper_Right.STL" />
      </geometry>
      <material
        name="">
        <color
          rgba="0.792156862745098 0.819607843137255 0.933333333333333 1" />
      </material>
    </visual>
    <collision>
      <origin
        xyz="0 0 0"
        rpy="0 0 0" />
      <geometry>
        <mesh
          filename="package://Student_Arm.SLDASM/meshes/Gripper_Right.STL" />
      </geometry>
    </collision>
  </link>
  <joint
    name="GR"
    type="prismatic">
    <origin
      xyz="-0.021806 0.072917 0.0747"
      rpy="-1.5708 0 -2.7325" />
    <parent
      link="J6" />
    <child
      link="Gripper_Right" />
    <axis
      xyz="0 0 1" />
    <limit
      lower="0"
      upper="0.057"
      effort="0"
      velocity="0" />
    <mimic
      joint="GL"
      multiplier="1"
      offset="0" />
  </joint>
</robot>